<?xml version="1.0"?>
<robot name="ma1400" xmlns:xacro="http://www.ros.org/wiki/xacro">
  <!-- Constants for robot dimensions -->
  <xacro:property name="PI" value="3.1415926535897931"/>
  <!-- Import all Gazebo-customization elements, including Gazebo colors -->
  <xacro:include filename="$(find ma1400_sim)/urdf/ma1400.gazebo" />

  <link name="world" />

  <link
    name="base_link">
    <inertial>
      <origin
        xyz="0.0659 0.0031108 0.04815"
        rpy="0 0 0" />
      <mass
        value="22.072" />
      <inertia
        ixx="0.50652"
        ixy="-0.0073335"
        ixz="-0.028252"
        iyy="0.36205"
        iyz="-0.010806"
        izz="0.24865" />
    </inertial>
    <visual>
      <origin
        xyz="0 0 0"
        rpy="0 0 0" />
      <geometry>
        <mesh
          filename="package://ma1400_sim/meshes/base_link.stl" />
      </geometry>
      <material
        name="Cast Carbon Steal">
        <color
          rgba="0.52941 0.54902 0.54902 1" />
      </material>
    </visual>
    <collision>
      <origin
        xyz="0 0 0"
        rpy="0 0 0" />
      <geometry>
        <mesh
          filename="package://ma1400_sim/meshes/base_link.stl" />
      </geometry>
    </collision>
  </link>

  <joint
    name="world2base"
    type="revolute">
    <origin
      xyz="0 0 0"
      rpy="0 -1.57079632679 0" />
    <parent
      link="world" />
    <child
      link="base_link" />
    <axis
      xyz="0 0 1" />
    <limit
      lower="0"
      upper="0"
      effort="0"
      velocity="0" />
  </joint>

  <link
    name="s_link">
    <inertial>
      <origin
        xyz="0.062654 -0.0075772 -0.0043747"
        rpy="0 0 0" />
      <!-- <mass
        value="0.03685" />
      <inertia
        ixx="6.5524E-05"
        ixy="-1.7002E-17"
        ixz="-6.5895E-18"
        iyy="4.591E-05"
        iyz="-5.1266E-06"
        izz="2.2509E-05" />
    </inertial> -->
    <!-- Taken from previous link, temporary! -->
      <mass
        value="22.072" />
      <inertia
        ixx="0.50652"
        ixy="-0.0073335"
        ixz="-0.028252"
        iyy="0.36205"
        iyz="-0.010806"
        izz="0.24865" />
    </inertial>
    <visual>
      <origin
        xyz="0 0 0"
        rpy="0 0 0" />
      <geometry>
        <mesh
          filename="package://ma1400_sim/meshes/s_link.stl" />
      </geometry>
      <material
        name="Cast Carbon Steal">
        <color
          rgba="0.52941 0.54902 0.54902 1" />
      </material>
    </visual>
    <collision>
      <origin
        xyz="0 0 0"
        rpy="0 0 0" />
      <geometry>
        <mesh
          filename="package://ma1400_sim/meshes/s_link.stl" />
      </geometry>
    </collision>
  </link>

  <joint
    name="joint_s"
    type="revolute">
    <origin
      xyz="0.0875 0 0"
      rpy="0 0 0" />
    <parent
      link="base_link" />
    <child
      link="s_link" />
    <axis
      xyz="1 0 0" />
    <limit
      lower="-2.9671"
      upper="2.9671"
      effort="0"
      velocity="3.8397" />
    <dynamics
      damping="0.7" />
  </joint>

  <link
    name="l_link">
    <inertial>
      <origin
        xyz="0.069501 0.26438 -9.7345E-05"
        rpy="0 0 0" />
      <mass
        value="30.269" />
      <inertia
        ixx="1.2747"
        ixy="-0.047351"
        ixz="-0.00033135"
        iyy="0.070602"
        iyz="0.00061639"
        izz="1.2616" />
    </inertial>
    <visual>
      <origin
        xyz="0 0 0"
        rpy="0 0 0" />
      <geometry>
        <mesh
          filename="package://ma1400_sim/meshes/l_link.stl" />
      </geometry>
      <material
        name="Cast Carbon Steal">
        <color
          rgba="0.52941 0.54902 0.54902 1" />
      </material>
    </visual>
    <collision>
      <origin
        xyz="0 0 0"
        rpy="0 0 0" />
      <geometry>
        <mesh
          filename="package://ma1400_sim/meshes/l_link.stl" />
      </geometry>
    </collision>
  </link>

  <joint
    name="joint_l"
    type="revolute">
    <origin
      xyz="0.3705 -0.0655 -0.15"
      rpy="-9.0409E-17 0 -1.5708" />
    <parent
      link="s_link" />
    <child
      link="l_link" />
    <axis
      xyz="-1 0 0" />
    <limit
      lower="-1.5708"
      upper="2.70526"
      effort="0"
      velocity="3.49066" />
    <dynamics
      damping="1.7" />
  </joint>

  <link
    name="u_link">
    <inertial>
      <origin
        xyz="0.10628 -0.068994 -0.050692"
        rpy="0 0 0" />
      <mass
        value="48.603" />
      <inertia
        ixx="0.67103"
        ixy="-0.023573"
        ixz="-0.022912"
        iyy="0.50654"
        iyz="-0.20689"
        izz="0.68713" />
    </inertial>
    <visual>
      <origin
        xyz="0 0 0"
        rpy="0 0 0" />
      <geometry>
        <mesh
          filename="package://ma1400_sim/meshes/u_link.stl" />
      </geometry>
      <material
        name="Cast Carbon Steal">
        <color
          rgba="0.75294 0.75294 0.75294 1" />
      </material>
    </visual>
    <collision>
      <origin
        xyz="0 0 0"
        rpy="0 0 0" />
      <geometry>
        <mesh
          filename="package://ma1400_sim/meshes/u_link.stl" />
      </geometry>
    </collision>
  </link>

  <joint
    name="joint_u"
    type="revolute">
    <origin
      xyz="0.0445 0.614 0"
      rpy="-9.0409E-17 0 3.1416" />
    <parent
      link="l_link" />
    <child
      link="u_link" />
    <axis
      xyz="1 0 0" />
    <limit
      lower="-3.31613"
      upper="3.05433"
      effort="0"
      velocity="3.83972" />
    <dynamics
      damping="1.7" />
  </joint>

  <link
    name="r_link">
    <inertial>
      <origin
        xyz="0.2743 0.0044679 -0.016296"
        rpy="0 0 0" />
      <mass
        value="13.33" />
      <inertia
        ixx="0.056428"
        ixy="-0.0016495"
        ixz="0.0069738"
        iyy="0.37608"
        iyz="0.00075742"
        izz="0.38768" />
    </inertial>
    <visual>
      <origin
        xyz="0 0 0"
        rpy="0 0 0" />
      <geometry>
        <mesh
          filename="package://ma1400_sim/meshes/r_link.stl" />
      </geometry>
      <material
        name="Cast Carbon Steal">
        <color
          rgba="0.52941 0.54902 0.54902 1" />
      </material>
    </visual>
    <collision>
      <origin
        xyz="0 0 0"
        rpy="0 0 0" />
      <geometry>
        <mesh
          filename="package://ma1400_sim/meshes/r_link.stl" />
      </geometry>
    </collision>
  </link>

  <joint
    name="joint_r"
    type="revolute">
    <origin
      xyz="0.109 -0.2 -0.069"
      rpy="1.5708 1.5708 0" />
    <parent
      link="u_link" />
    <child
      link="r_link" />
    <axis
      xyz="1 0 0" />
    <limit
      lower="-2.61799"
      upper="2.61799"
      effort="14"
      velocity="3.22886" />
    <dynamics
      damping="1.7" />
  </joint>

  <link
    name="b_link">
    <inertial>
      <origin
        xyz="0.056214 0.092191 0.012761"
        rpy="0 0 0" />
      <mass
        value="4.0209" />
      <inertia
        ixx="0.024141"
        ixy="-0.0015461"
        ixz="-0.00057354"
        iyy="0.0086318"
        iyz="-0.0030317"
        izz="0.026048" />
    </inertial>
    <visual>
      <origin
        xyz="0 0 0"
        rpy="0 0 0" />
      <geometry>
        <mesh
          filename="package://ma1400_sim/meshes/b_link.stl" />
      </geometry>
      <material
        name="Cast Carbon Steal">
        <color
          rgba="0.52941 0.54902 0.54902 1" />
      </material>
    </visual>
    <collision>
      <origin
        xyz="0 0 0"
        rpy="0 0 0" />
      <geometry>
        <mesh
          filename="package://ma1400_sim/meshes/b_link.stl" />
      </geometry>
    </collision>
  </link>

  <joint
    name="joint_b"
    type="revolute">
    <origin
      xyz="0.571 0.07 0"
      rpy="-1.5708 0 -1.5708" />
    <parent
      link="r_link" />
    <child
      link="b_link" />
    <axis
      xyz="-1 0 0" />
    <limit
      lower="-0.785398"
      upper="3.14159"
      effort="14"
      velocity="2.86234" />
    <dynamics
      damping="1.7" />
  </joint>

  <link
    name="t_link">
    <inertial>
      <origin
        xyz="0.041051 -1.0193E-05 -1.6479E-05"
        rpy="0 0 0" />
      <mass
        value="1.3027" />
      <inertia
        ixx="0.0012142"
        ixy="-5.0796E-07"
        ixz="1.2468E-06"
        iyy="0.0011156"
        iyz="2.6778E-06"
        izz="0.0011096" />
    </inertial>
    <visual>
      <origin
        xyz="0 0 0"
        rpy="0 0 0" />
      <geometry>
        <mesh
          filename="package://ma1400_sim/meshes/t_link.stl" />
      </geometry>
      <material
        name="Cast Carbon Steal">
        <color
          rgba="0.52941 0.54902 0.54902 1" />
      </material>
    </visual>
    <collision>
      <origin
        xyz="0 0 0"
        rpy="0 0 0" />
      <geometry>
        <mesh
          filename="package://ma1400_sim/meshes/t_link.stl" />
      </geometry>
    </collision>
  </link>

  <joint
    name="joint_t"
    type="revolute">
    <origin
      xyz="0.07 0.1265 0.03"
      rpy="0 0 1.5708" />
    <parent
      link="b_link" />
    <child
      link="t_link" />
    <axis
      xyz="-1 0 0" />
    <limit
      lower="-3.49066"
      upper="3.49066"
      effort="0.98"
      velocity="10.6465" />
  <dynamics
      damping="0.7" />
</joint>

  <transmission name="s_trans">
    <type>transmission_interface/SimpleTransmission</type>
    <actuator name="$s_motor">
      <mechanicalReduction>1</mechanicalReduction>
    </actuator>
    <joint name="joint_s">
      <hardwareInterface>PositionJointInterface</hardwareInterface>
    </joint>
  </transmission>

  <transmission name="l_trans">
    <type>transmission_interface/SimpleTransmission</type>
    <actuator name="$l_motor">
      <mechanicalReduction>1</mechanicalReduction>
    </actuator>
    <joint name="joint_l">
      <hardwareInterface>PositionJointInterface</hardwareInterface>
    </joint>
  </transmission>

  <transmission name="u_trans">
    <type>transmission_interface/SimpleTransmission</type>
    <actuator name="$u_motor">
      <mechanicalReduction>1</mechanicalReduction>
    </actuator>
    <joint name="joint_u">
      <hardwareInterface>PositionJointInterface</hardwareInterface>
    </joint>
  </transmission>

  <transmission name="r_trans">
    <type>transmission_interface/SimpleTransmission</type>
    <actuator name="$r_motor">
      <mechanicalReduction>1</mechanicalReduction>
    </actuator>
    <joint name="joint_r">
      <hardwareInterface>PositionJointInterface</hardwareInterface>
    </joint>
  </transmission>

  <transmission name="b_trans">
    <type>transmission_interface/SimpleTransmission</type>
    <actuator name="$b_motor">
      <mechanicalReduction>1</mechanicalReduction>
    </actuator>
    <joint name="joint_b">
      <hardwareInterface>PositionJointInterface</hardwareInterface>
    </joint>
  </transmission>

  <transmission name="t_trans">
    <type>transmission_interface/SimpleTransmission</type>
    <actuator name="$t_motor">
      <mechanicalReduction>1</mechanicalReduction>
    </actuator>
    <joint name="joint_t">
      <hardwareInterface>PositionJointInterface</hardwareInterface>
    </joint>
  </transmission>

</robot>
